Workbook

Sheet customers
A1: Customer_ID | B1: Acquisition_Date | C1: Acquisition_Channel | D1: Monthly_Revenue | E1: Status | F1: Churn_Date | G1: Cohort_Month
A2: C001 | B2: 45662 | C2: Google Ads | D2: 2000 | E2: Active | G2: 45658
A3: C002 | B3: 45665 | C3: Referral | D3: 3000 | E3: Active | G3: 45658
A4: C003 | B4: 45669 | C4: LinkedIn | D4: 2500 | F4: 45767 | G4: 45658
A5: C004 | B5: 45675 | C5: Organic | D5: 1800 | E5: Active | G5: 45658
A6: C005 | B6: 45682 | C6: Meta Ads | D6: 2200 | E6: Active | G6: 45658
A7: C006 | B7: 45691 | C7: Google Ads | D7: 2500 | E7: Active | G7: 45689
A8: C007 | B8: 45698 | C8: Referral | D8: 3200 | E8: Active | G8: 45689
A9: C008 | B9: 45703 | C9: LinkedIn | D9: 2800 | F9: 45807 | G9: 45689
A10: C009 | B10: 45708 | C10: Organic | D10: 2000 | E10: Active | G10: 45689
A11: C010 | B11: 45713 | C11: Meta Ads | D11: 2400 | E11: Active | G11: 45689
A12: C011 | B12: 45727 | C12: Meta Ads | D12: 2302 | E12: Active | G12: 45717
A13: C012 | B13: 45719 | C13: Organic | D13: 1748 | E13: Active | G13: 45717
A14: C013 | B14: 45718 | C14: Meta Ads | D14: 2209 | F14: 45833 | G14: 45717
A15: C014 | B15: 45730 | C15: Google Ads | D15: 2092 | E15: Active | G15: 45717
A16: C015 | B16: 45718 | C16: Organic | D16: 1763 | E16: Active | G16: 45717
A17: C016 | B17: 45737 | C17: LinkedIn | D17: 2885 | F17: 45871 | G17: 45717
A18: C017 | B18: 45760 | C18: Google Ads | D18: 2226 | F18: 45837 | G18: 45748
A19: C018 | B19: 45757 | C19: Referral | D19: 3176 | F19: 45856 | G19: 45748
A20: C019 | B20: 45765 | C20: Organic | D20: 1792 | F20: 45898 | G20: 45748
A21: C020 | B21: 45768 | C21: Google Ads | D21: 2099 | E21: Active | G21: 45748
A22: C021 | B22: 45750 | C22: LinkedIn | D22: 2716 | E22: Active | G22: 45748
A23: C022 | B23: 45769 | C23: LinkedIn | D23: 2797 | E23: Active | G23: 45748
A24: C023 | B24: 45766 | C24: Meta Ads | D24: 2285 | E24: Active | G24: 45748
A25: C024 | B25: 45803 | C25: Google Ads | D25: 2249 | F25: 45901 | G25: 45778
A26: C025 | B26: 45794 | C26: LinkedIn | D26: 2575 | E26: Active | G26: 45778
A27: C026 | B27: 45787 | C27: LinkedIn | D27: 2437 | F27: 45900 | G27: 45778
A28: C027 | B28: 45783 | C28: Organic | D28: 1777 | E28: Active | G28: 45778
A29: C028 | B29: 45791 | C29: Google Ads | D29: 2079 | E29: Active | G29: 45778
A30: C029 | B30: 45796 | C30: Organic | D30: 1860 | E30: Active | G30: 45778
A31: C030 | B31: 45789 | C31: LinkedIn | D31: 2696 | E31: Active | G31: 45778
A32: C031 | B32: 45780 | C32: Organic | D32: 1838 | E32: Active | G32: 45778
A33: C032 | B33: 45830 | C33: Google Ads | D33: 2317 | E33: Active | G33: 45809
A34: C033 | B34: 45830 | C34: Organic | D34: 1845 | E34: Active | G34: 45809
A35: C034 | B35: 45837 | C35: Organic | D35: 1711 | E35: Active | G35: 45809
A36: C035 | B36: 45820 | C36: Google Ads | D36: 2119 | E36: Active | G36: 45809
A37: C036 | B37: 45815 | C37: Organic | D37: 1766 | E37: Active | G37: 45809
A38: C037 | B38: 45821 | C38: Referral | D38: 3346 | E38: Active | G38: 45809
A39: C038 | B39: 45814 | C39: Referral | D39: 3181 | E39: Active | G39: 45809
... A41: C040 | B41: 45822 | C41: Meta Ads | D41: 2449 | E41: Active | G41: 45809
...

Sheet revenue
A1: Month | B1: New Customers | C1: Active Customers | D1: Monthly Revenue | E1: Growth
A2: 45658 | B2: 35 | C2: 35 | D2: 175000 | E2: N/A
A3: 45689 | B3: 42 | C3: 72 | D3: 360000 | E3: =(D3-D2)/D2 -> 1.0571429
A4: 45717 | B4: 48 | C4: 111 | D4: 555000 | E4: =(D4-D3)/D3 -> 0.54166667
A5: 45748 | B5: 55 | C5: 157 | D5: 785000 | E5: =(D5-D4)/D4 -> 0.41441441
A6: 45778 | B6: 63 | C6: 214 | D6: 1070000 | E6: =(D6-D5)/D5 -> 0.36305732
A7: 45809 | B7: 70 | C7: 277 | D7: 1385000 | E7: =(D7-D6)/D6 -> 0.29439252
A8: 45839 | B8: 78 | C8: 346 | D8: 1730000 | E8: =(D8-D7)/D7 -> 0.24909747
A9: 45870 | B9: 85 | C9: 421 | D9: 2105000 | E9: =(D9-D8)/D8 -> 0.21676301
A10: 45901 | B10: 92 | C10: 494 | D10: 2470000 | E10: =(D10-D9)/D9 -> 0.17339667
A11: 45931 | B11: 100 | C11: 567 | D11: 2835000 | E11: =(D11-D10)/D10 -> 0.14777328
A12: 45962 | B12: 108 | C12: 642 | D12: 3210000 | E12: =(D12-D11)/D11 -> 0.13227513
A13: 45992 | B13: 115 | C13: 710 | D13: 3550000 | E13: =(D13-D12)/D12 -> 0.105919

Sheet expenses
A1: Month | B1: Marketing | C1: Salaries | D1: Infrastructure | E1: Software | F1: Operations | G1: Total Expenses
A2: 45658 | B2: 180000 | C2: 450000 | D2: 70000 | E2: 30000 | F2: 50000 | G2: =SUM(B2:F2) -> 780000
A3: 45689 | B3: 200000 | C3: 450000 | D3: 75000 | E3: 32000 | F3: 55000 | G3: =SUM(B3:F3) -> 812000
A4: 45717 | B4: 230000 | C4: 480000 | D4: 80000 | E4: 35000 | F4: 60000 | G4: =SUM(B4:F4) -> 885000
A5: 45748 | B5: 250000 | C5: 500000 | D5: 85000 | E5: 38000 | F5: 65000 | G5: =SUM(B5:F5) -> 938000
A6: 45778 | B6: 280000 | C6: 520000 | D6: 90000 | E6: 40000 | F6: 70000 | G6: =SUM(B6:F6) -> 1000000
A7: 45809 | B7: 300000 | C7: 550000 | D7: 95000 | E7: 42000 | F7: 75000 | G7: =SUM(B7:F7) -> 1062000
A8: 45839 | B8: 320000 | C8: 580000 | D8: 100000 | E8: 45000 | F8: 80000 | G8: =SUM(B8:F8) -> 1125000
A9: 45870 | B9: 340000 | C9: 600000 | D9: 105000 | E9: 48000 | F9: 85000 | G9: =SUM(B9:F9) -> 1178000
A10: 45901 | B10: 360000 | C10: 620000 | D10: 110000 | E10: 50000 | F10: 90000 | G10: =SUM(B10:F10) -> 1230000
A11: 45931 | B11: 380000 | C11: 650000 | D11: 115000 | E11: 52000 | F11: 95000 | G11: =SUM(B11:F11) -> 1292000
A12: 45962 | B12: 400000 | C12: 680000 | D12: 120000 | E12: 55000 | F12: 100000 | G12: =SUM(B12:F12) -> 1355000
A13: 45992 | B13: 420000 | C13: 700000 | D13: 125000 | E13: 58000 | F13: 105000 | G13: =SUM(B13:F13) -> 1408000

Sheet marketing
A1: Month | B1: Google Ads | C1: Meta Ads | D1: LinkedIn | E1: Referral | F1: Other | G1: Total Marketing
A2: 45658 | B2: 80000 | C2: 40000 | D2: 30000 | E2: 10000 | F2: 20000 | G2: =SUM(B2:F2) -> 180000
A3: 45689 | B3: 90000 | C3: 45000 | D3: 35000 | E3: 12000 | F3: 18000 | G3: =SUM(B3:F3) -> 200000
A4: 45717 | B4: 100000 | C4: 50000 | D4: 40000 | E4: 15000 | F4: 25000 | G4: =SUM(B4:F4) -> 230000
A5: 45748 | B5: 110000 | C5: 55000 | D5: 45000 | E5: 16000 | F5: 24000 | G5: =SUM(B5:F5) -> 250000
A6: 45778 | B6: 125000 | C6: 60000 | D6: 50000 | E6: 18000 | F6: 27000 | G6: =SUM(B6:F6) -> 280000
A7: 45809 | B7: 135000 | C7: 65000 | D7: 55000 | E7: 20000 | F7: 25000 | G7: =SUM(B7:F7) -> 300000
A8: 45839 | B8: 145000 | C8: 70000 | D8: 60000 | E8: 22000 | F8: 23000 | G8: =SUM(B8:F8) -> 320000
A9: 45870 | B9: 155000 | C9: 75000 | D9: 65000 | E9: 24000 | F9: 21000 | G9: =SUM(B9:F9) -> 340000
A10: 45901 | B10: 165000 | C10: 80000 | D10: 70000 | E10: 26000 | F10: 19000 | G10: =SUM(B10:F10) -> 360000
A11: 45931 | B11: 175000 | C11: 85000 | D11: 75000 | E11: 28000 | F11: 17000 | G11: =SUM(B11:F11) -> 380000
A12: 45962 | B12: 185000 | C12: 90000 | D12: 80000 | E12: 30000 | F12: 15000 | G12: =SUM(B12:F12) -> 400000
A13: 45992 | B13: 195000 | C13: 95000 | D13: 85000 | E13: 32000 | F13: 13000 | G13: =SUM(B13:F13) -> 420000

Sheet KPI_cal
A1: Month | B1: Revenue | C1: Total Expenses | D1: Burn Rate | E1: Active Customers | F1: CAC | G1: ARPU | H1: Run Rate | I1: Gross Margin % | J1: Monthly Churn % | K1: LTV | L1: LTV:CAC
A2: 45658 | B2: =revenue!D2 -> 175000 | C2: =expenses!G2 -> 780000 | D2: =C2-B2 -> 605000 | E2: =revenue!C2 -> 35 | F2: =marketing!G2/revenue!B2 -> 5142.8571 | G2: =B2/E2 -> 5000 | H2: 2100000 | I2: 0.75 | J2: 0.03 | K2: =G2*I2/J2 -> 125000 | L2: =K2/F2 -> 24.305556
A3: 45689 | B3: =revenue!D3 -> 360000 | C3: =expenses!G3 -> 812000 | D3: =C3-B3 -> 452000 | E3: =revenue!C3 -> 72 | F3: =marketing!G3/revenue!B3 -> 4761.9048 | G3: =B3/E3 -> 5000 | H3: 4320000 | I3: 0.75 | J3: 0.03 | K3: =G3*I3/J3 -> 125000 | L3: =K3/F3 -> 26.25
A4: 45717 | B4: =revenue!D4 -> 555000 | C4: =expenses!G4 -> 885000 | D4: =C4-B4 -> 330000 | E4: =revenue!C4 -> 111 | F4: =marketing!G4/revenue!B4 -> 4791.6667 | G4: =B4/E4 -> 5000 | H4: 6660000 | I4: 0.75 | J4: 0.03 | K4: =G4*I4/J4 -> 125000 | L4: =K4/F4 -> 26.086957
A5: 45748 | B5: =revenue!D5 -> 785000 | C5: =expenses!G5 -> 938000 | D5: =C5-B5 -> 153000 | E5: =revenue!C5 -> 157 | F5: =marketing!G5/revenue!B5 -> 4545.4545 | G5: =B5/E5 -> 5000 | H5: 9420000 | I5: 0.75 | J5: 0.03 | K5: =G5*I5/J5 -> 125000 | L5: =K5/F5 -> 27.5
A6: 45778 | B6: =revenue!D6 -> 1070000 | C6: =expenses!G6 -> 1000000 | D6: =C6-B6 -> -70000 | E6: =revenue!C6 -> 214 | F6: =marketing!G6/revenue!B6 -> 4444.4444 | G6: =B6/E6 -> 5000 | H6: 12840000 | I6: 0.75 | J6: 0.03 | K6: =G6*I6/J6 -> 125000 | L6: =K6/F6 -> 28.125
A7: 45809 | B7: =revenue!D7 -> 1385000 | C7: =expenses!G7 -> 1062000 | D7: =C7-B7 -> -323000 | E7: =revenue!C7 -> 277 | F7: =marketing!G7/revenue!B7 -> 4285.7143 | G7: =B7/E7 -> 5000 | H7: 16620000 | I7: 0.75 | J7: 0.03 | K7: =G7*I7/J7 -> 125000 | L7: =K7/F7 -> 29.166667
A8: 45839 | B8: =revenue!D8 -> 1730000 | C8: =expenses!G8 -> 1125000 | D8: =C8-B8 -> -605000 | E8: =revenue!C8 -> 346 | F8: =marketing!G8/revenue!B8 -> 4102.5641 | G8: =B8/E8 -> 5000 | H8: 20760000 | I8: 0.75 | J8: 0.03 | K8: =G8*I8/J8 -> 125000 | L8: =K8/F8 -> 30.46875
A9: 45870 | B9: =revenue!D9 -> 2105000 | C9: =expenses!G9 -> 1178000 | D9: =C9-B9 -> -927000 | E9: =revenue!C9 -> 421 | F9: =marketing!G9/revenue!B9 -> 4000 | G9: =B9/E9 -> 5000 | H9: 25260000 | I9: 0.75 | J9: 0.03 | K9: =G9*I9/J9 -> 125000 | L9: =K9/F9 -> 31.25
A10: 45901 | B10: =revenue!D10 -> 2470000 | C10: =expenses!G10 -> 1230000 | D10: =C10-B10 -> -1240000 | E10: =revenue!C10 -> 494 | F10: =marketing!G10/revenue!B10 -> 3913.0435 | G10: =B10/E10 -> 5000 | H10: 29640000 | I10: 0.75 | J10: 0.03 | K10: =G10*I10/J10 -> 125000 | L10: =K10/F10 -> 31.944444
A11: 45931 | B11: =revenue!D11 -> 2835000 | C11: =expenses!G11 -> 1292000 | D11: =C11-B11 -> -1543000 | E11: =revenue!C11 -> 567 | F11: =marketing!G11/revenue!B11 -> 3800 | G11: =B11/E11 -> 5000 | H11: 34020000 | I11: 0.75 | J11: 0.03 | K11: =G11*I11/J11 -> 125000 | L11: =K11/F11 -> 32.894737
A12: 45962 | B12: =revenue!D12 -> 3210000 | C12: =expenses!G12 -> 1355000 | D12: =C12-B12 -> -1855000 | E12: =revenue!C12 -> 642 | F12: =marketing!G12/revenue!B12 -> 3703.7037 | G12: =B12/E12 -> 5000 | H12: 38520000 | I12: 0.75 | J12: 0.03 | K12: =G12*I12/J12 -> 125000 | L12: =K12/F12 -> 33.75
A13: 45992 | B13: =revenue!D13 -> 3550000 | C13: =expenses!G13 -> 1408000 | D13: =C13-B13 -> -2142000 | E13: =revenue!C13 -> 710 | F13: =marketing!G13/revenue!B13 -> 3652.1739 | G13: =B13/E13 -> 5000 | H13: 42600000 | I13: 0.75 | J13: 0.03 | K13: =G13*I13/J13 -> 125000 | L13: =K13/F13 -> 34.22619

Sheet cohort analysis
A1: Cohort Month | B1: Month 0 | C1: Month 1 | D1: Month 2 | E1: Month 3 | F1: Month 4 | G1: Month 5 | H1: Month 6 | I1: Month 7 | J1: Month 8 | K1: Month 9 | L1: Month 10 | M1: Month 11
A2: 45658 | B2: 5 | C2: 5 | D2: 4 | E2: 4 | F2: 4 | G2: 3 | H2: 3 | I2: 3 | J2: 3 | K2: 3 | L2: 3 | M2: 3
A3: 45689 | B3: 5 | C3: 5 | D3: 5 | E3: 4 | F3: 4 | G3: 4 | H3: 3 | I3: 3 | J3: 3 | K3: 3 | L3: 3 | M3: 3
A4: 45717 | B4: 7 | C4: 7 | D4: 6 | E4: 6 | F4: 5 | G4: 5 | H4: 4 | I4: 4 | J4: 4 | K4: 4 | L4: 4 | M4: 4
A5: 45748 | B5: 8 | C5: 8 | D5: 7 | E5: 7 | F5: 6 | G5: 6 | H5: 5 | I5: 5 | J5: 5 | K5: 5 | L5: 5 | M5: 5
A6: 45778 | B6: 9 | C6: 9 | D6: 8 | E6: 7 | F6: 7 | G6: 6 | H6: 6 | I6: 6 | J6: 5 | K6: 5 | L6: 5 | M6: 5
A7: 45809 | B7: 10 | C7: 10 | D7: 9 | E7: 8 | F7: 8 | G7: 7 | H7: 7 | I7: 6 | J7: 6 | K7: 6 | L7: 6 | M7: 6
A8: 45839 | B8: 10 | C8: 10 | D8: 9 | E8: 9 | F8: 8 | G8: 8 | H8: 7 | I8: 7 | J8: 7 | K8: 7 | L8: 7 | M8: 7
A9: 45870 | B9: 11 | C9: 11 | D9: 10 | E9: 9 | F9: 9 | G9: 8 | H9: 8 | I9: 8 | J9: 7 | K9: 7 | L9: 7 | M9: 7
A10: 45901 | B10: 10 | C10: 10 | D10: 9 | E10: 9 | F10: 8 | G10: 8 | H10: 7 | I10: 7 | J10: 7 | K10: 7 | L10: 7 | M10: 7
A11: 45931 | B11: 9 | C11: 9 | D11: 8 | E11: 8 | F11: 7 | G11: 7 | H11: 6 | I11: 6 | J11: 6 | K11: 6 | L11: 6 | M11: 6
A12: 45962 | B12: 11 | C12: 11 | D12: 10 | E12: 9 | F12: 9 | G12: 8 | H12: 8 | I12: 7 | J12: 7 | K12: 7 | L12: 7 | M12: 7
A13: 45992 | B13: 10 | C13: 10 | D13: 9 | E13: 8 | F13: 8 | G13: 7 | H13: 7 | I13: 6 | J13: 6 | K13: 5 | L13: 5 | M13: 5
